File: Data on material properties/Concrete-stress-strain-Tongji/C40.txt
Specimen 1
The tested complete stress-strain curves
of concrete under uniaxial compression
Strain, Stress (MPa)
0,0
0.0002,8.91536
0.0004,16.49347
0.0006,23.44389
0.0008,29.73393
0.001,35.2321
0.0012,39.99216
0.0014,43.81583
0.0016,46.52439
0.0018,46.68577
0.002,45.65971
0.0022,44.13438
0.0024,41.42427
0.0026,38.02296
0.0028,34.59784
0.003,31.81086
0.0032,29.61844
0.0034,27.63432
0.0036,25.73169
0.0038,23.80202
0.004,21.90296
0.0042,20.18087
0.0044,18.7108
0.0046,17.40368
0.0048,16.2228
0.005,15.13821
0.0052,14.16449
0.0054,13.31167
0.0056,12.55721
0.0058,11.94164
0.006,11.45522
0.0062,10.95606
0.0064,10.38249
0.0066,9.95545

Specimen 2
The tested complete stress-strain curves
of concrete under uniaxial compression
Strain, Stress (MPa)
0,0
0.0002,8.52941
0.0004,16.3458
0.0006,23.56529
0.0008,29.97963
0.001,35.42848
0.0012,40.02404
0.0014,43.7768
0.0016,46.59809
0.0018,48.22237
0.002,48.90245
0.0022,47.74898
0.0024,45.0982
0.0026,41.58442
0.0028,37.84198
0.003,34.5052
0.0032,31.90874
0.0034,29.47045
0.0036,27.18626
0.0038,25.09577
0.004,23.13858
0.0042,21.31338
0.0044,19.63532
0.0046,18.11478
0.0048,16.72376
0.005,15.41613
0.0052,14.14315
0.0054,12.89568
0.0056,11.746
0.0058,10.76498
0.006,9.92273
0.0062,9.16524
0.0064,8.45244
0.0066,7.78966

Specimen 3
The tested complete stress-strain curves
of concrete under uniaxial compression
Strain, Stress (MPa)
0,0
0.0002,8.0112
0.0004,15.16203
0.0006,21.68147
0.0008,27.77913
0.001,33.78657
0.0012,38.84307
0.0014,42.67807
0.0016,43.51224
0.0018,43.53814
0.002,43.11971
0.0022,42.04832
0.0024,40.45454
0.0026,38.46894
0.0028,36.22208
0.003,33.84452
0.0032,31.46683
0.0034,29.21956
0.0036,27.04248
0.0038,24.58124
0.004,22.35813
0.0042,20.7996
0.0044,19.57808
0.0046,18.38621
0.0048,17.07357
0.005,15.76298
0.0052,14.56533
0.0054,13.47451
0.0056,12.4774
0.0058,11.59859
0.006,10.81873
0.0062,10.10633
0.0064,9.45797
0.0066,8.84701

Specimen 4
The tested complete stress-strain curves
of concrete under uniaxial compression
Strain, Stress (MPa)
0,0
0.0002,8.02177
0.0004,15.55946
0.0006,22.5018
0.0008,28.61651
0.001,33.6476
0.0012,37.96011
0.0014,41.44024
0.0016,43.87708
0.0018,44.67516
0.002,44.56197
0.0022,44.16579
0.0024,42.69076
0.0026,40.54513
0.0028,38.31025
0.003,35.96507
0.0032,33.23856
0.0034,30.38433
0.0036,27.65612
0.0038,25.29019
0.004,23.14261
0.0042,21.13832
0.0044,19.31365
0.0046,17.69021
0.0048,16.21516
0.005,14.94787
0.0052,13.94227
0.0054,13.11189
0.0056,12.3658
0.0058,11.68396
0.006,11.06221
0.0062,10.47855
0.0064,9.94609
0.0066,9.48468

Specimen 5
The tested complete stress-strain curves
of concrete under uniaxial compression
Strain, Stress (MPa)
0,0
0.0002,7.89723
0.0004,15.26436
0.0006,21.83209
0.0008,27.65918
0.001,32.84732
0.0012,36.65754
0.0014,39.59472
0.0016,41.36589
0.0018,42.32708
0.002,42.73195
0.0022,42.91208
0.0024,42.3968
0.0026,41.33747
0.0028,39.66384
0.003,37.71815
0.0032,35.33488
0.0034,32.6232
0.0036,29.81033
0.0038,27.12349
0.004,24.78695
0.0042,22.76352
0.0044,20.89814
0.0046,19.11882
0.0048,17.3778
0.005,15.73007
0.0052,14.248
0.0054,12.93523
0.0056,11.755
0.0058,10.73896
0.006,9.84527
0.0062,9.10126
0.0064,8.55619
0.0066,8.12805

Specimen 6
The tested complete stress-strain curves
of concrete under uniaxial compression
Strain, Stress (MPa)
0,0
0.0002,8.28942
0.0004,15.1956
0.0006,21.61636
0.0008,27.38172
0.001,32.54673
0.0012,36.50744
0.0014,39.72537
0.0016,40.28654
0.0018,40.20612
0.002,40.06278
0.0022,39.44276
0.0024,38.06689
0.0026,36.35354
0.0028,34.63245
0.003,32.55105
0.0032,30.18084
0.0034,27.72894
0.0036,25.40247
0.0038,23.40854
0.004,21.71818
0.0042,20.16274
0.0044,18.72737
0.0046,17.39719
0.0048,16.14744
0.005,14.96331
0.0052,13.87865
0.0054,12.92917
0.0056,12.11473
0.0058,11.38974
0.006,10.76297
0.0062,10.24087
0.0064,9.79856
0.0066,9.41332

Specimen 7
The tested complete stress-strain curves
of concrete under uniaxial compression
Strain, Stress (MPa)
0,0
0.0002,8.22799
0.0004,15.50812
0.0006,22.09687
0.0008,28.21592
0.001,32.98242
0.0012,35.6325
0.0014,36.48952
0.0016,36.64876
0.0018,35.86093
0.002,34.32178
0.0022,32.32155
0.0024,30.15049
0.0026,28.09882
0.0028,26.45679
0.003,25.27772
0.0032,24.23688
0.0034,23.27735
0.0036,22.34985
0.0038,21.4478
0.004,20.59239
0.0042,19.79717
0.0044,19.07247
0.0046,18.40278
0.0048,17.76059
0.005,17.13357
0.0052,16.53487
0.0054,15.93139
0.0056,15.28319
0.0058,14.58149
0.006,13.89478
0.0062,13.29419
0.0064,12.77427
0.0066,12.29136

Specimen 8
The tested complete stress-strain curves
of concrete under uniaxial compression
Strain, Stress (MPa)
0,0
0.0002,6.89147
0.0004,14.0255
0.0006,20.61492
0.0008,26.67109
0.001,31.61965
0.0012,35.50551
0.0014,38.52503
0.0016,40.12856
0.0018,40.41903
0.002,40.56484
0.0022,40.38128
0.0024,39.33429
0.0026,37.85933
0.0028,36.11185
0.003,33.61168
0.0032,30.65829
0.0034,27.58831
0.0036,24.73838
0.0038,22.44512
0.004,20.74521
0.0042,19.23747
0.0044,17.92205
0.0046,16.80992
0.0048,15.90188
0.005,15.14503
0.0052,14.48753
0.0054,13.88162
0.0056,13.32485
0.0058,12.81986
0.006,12.3612
0.0062,11.95714
0.0064,11.5793
0.0066,11.1841

Specimen 9
The tested complete stress-strain curves
of concrete under uniaxial compression
Strain, Stress (MPa)
0,0
0.0002,9.03626
0.0004,16.63898
0.0006,23.56451
0.0008,29.54773
0.001,34.63713
0.0012,38.80402
0.0014,41.48355
0.0016,42.32394
0.0018,42.76891
0.002,42.41621
0.0022,40.65915
0.0024,38.16653
0.0026,35.69818
0.0028,33.41889
0.003,30.89629
0.0032,28.26576
0.0034,25.6667
0.0036,23.23851
0.0038,21.12058
0.004,19.36488
0.0042,17.78992
0.0044,16.35874
0.0046,15.046
0.0048,13.82548
0.005,12.65702
0.0052,11.56483
0.0054,10.59772
0.0056,9.80321
0.0058,9.13142
0.006,8.55536
0.0062,8.10382
0.0064,7.77372
0.0066,7.51091

Specimen 10
The tested complete stress-strain curves
of concrete under uniaxial compression
Strain, Stress (MPa)
0,0
0.0002,7.42371
0.0004,13.54624
0.0006,19.14866
0.0008,23.86841
0.001,27.35082
0.0012,29.33962
0.0014,31.44469
0.0016,31.92067
0.0018,31.50116
0.002,30.82894
0.0022,30.03587
0.0024,29.25386
0.0026,28.53623
0.0028,27.76308
0.003,26.88497
0.0032,25.82876
0.0034,24.40533
0.0036,22.77146
0.0038,21.15392
0.004,19.7795
0.0042,18.74032
0.0044,17.837
0.0046,17.03888
0.0048,16.32419
0.005,15.68472
0.0052,15.11005
0.0054,14.58492
0.0056,14.10782
0.0058,13.67141
0.006,13.24999
0.0062,12.8359
0.0064,12.43512
0.0066,12.03709

Specimen 11
The tested complete stress-strain curves
of concrete under uniaxial compression
Strain, Stress (MPa)
0,0
0.0002,8.76321
0.0004,15.50158
0.0006,22.10811
0.0008,27.31025
0.001,30.84643
0.0012,32.99418
0.0014,34.32763
0.0016,35.25218
0.0018,35.50916
0.002,35.36649
0.0022,35.07856
0.0024,34.2557
0.0026,32.54543
0.0028,30.57749
0.003,28.95613
0.0032,27.54391
0.0034,26.18465
0.0036,24.87564
0.0038,23.61415
0.004,22.37708
0.0042,21.17176
0.0044,20.04346
0.0046,19.03686
0.0048,18.14634
0.005,17.33543
0.0052,16.58029
0.0054,15.8638
0.0056,15.19068
0.0058,14.56374
0.006,13.98874
0.0062,13.46581
0.0064,12.9605
0.0066,12.43598

Specimen 12
The tested complete stress-strain curves
of concrete under uniaxial compression
Strain, Stress (MPa)
0,0
0.0002,7.49331
0.0004,14.2417
0.0006,20.4553
0.0008,26.8154
0.001,32.0038
0.0012,35.4513
0.0014,36.7434
0.0016,36.9366
0.0018,36.199
0.002,35.3343
0.0022,34.2961
0.0024,32.934
0.0026,31.4152
0.0028,29.5521
0.003,27.7995
0.0032,26.3876
0.0034,24.9943
0.0036,23.7904
0.0038,22.7981
0.004,21.6554
0.0042,20.6045
0.0044,19.6568
0.0046,18.8672
0.0048,18.1584
0.005,17.4933
0.0052,16.8824
0.0054,16.2612
0.0056,15.5904
0.0058,15.0006
0.006,14.3818
0.0062,13.9103
0.0064,13.4565
0.0066,13.0185

Specimen 13
The tested complete stress-strain curves
of concrete under uniaxial compression
Strain, Stress (MPa)
0,0
0.0002,7.87764
0.0004,15.3068
0.0006,22.3427
0.0008,28.8746
0.001,34.7251
0.0012,39.815
0.0014,43.6649
0.0016,46.2209
0.0018,47.7726
0.002,47.382
0.0022,44.8777
0.0024,41.2644
0.0026,38.2416
0.0028,36.1452
0.003,33.3889
0.0032,30.2653
0.0034,27.4001
0.0036,24.8916
0.0038,22.7819
0.004,20.9637
0.0042,19.4215
0.0044,18.0272
0.0046,16.8716
0.0048,15.8308
0.005,14.8907
0.0052,13.9116
0.0054,13.0482
0.0056,12.3796
0.0058,11.8243
0.006,11.3013
0.0062,10.8678
0.0064,10.4816
0.0066,10.1516

Specimen 14
The tested complete stress-strain curves
of concrete under uniaxial compression
Strain, Stress (MPa)
0,0
0.0002,7.82824
0.0004,14.7484
0.0006,21.3143
0.0008,27.4543
0.001,32.8606
0.0012,37.2297
0.0014,40.3978
0.0016,41.7382
0.0018,41.7315
0.002,40.8336
0.0022,38.8848
0.0024,38.2982
0.0026,37.0336
0.0028,34.7826
0.003,32.3465
0.0032,30.0733
0.0034,28.3184
0.0036,26.8668
0.0038,25.5059
0.004,24.0968
0.0042,22.5925
0.0044,21.0538
0.0046,19.7876
0.0048,18.7835
0.005,18.0629
0.0052,17.4444
0.0054,16.8415
0.0056,16.2554
0.0058,15.5683
0.006,14.973
0.0062,14.415
0.0064,13.7892
0.0066,13.1151

Specimen 15
The tested complete stress-strain curves
of concrete under uniaxial compression
Strain, Stress (MPa)
0,0
0.0002,7.21873
0.0004,13.8118
0.0006,20.0655
0.0008,25.6524
0.001,29.833
0.0012,33.4881
0.0014,35.8004
0.0016,37.2854
0.0018,38.4836
0.002,38.897
0.0022,38.7568
0.0024,37.4549
0.0026,35.3523
0.0028,34.0331
0.003,32.7148
0.0032,31.1319
0.0034,29.8288
0.0036,27.953
0.0038,25.9252
0.004,24.0055
0.0042,22.5455
0.0044,21.3349
0.0046,20.0836
0.0048,18.9069
0.005,17.8721
0.0052,16.8124
0.0054,15.7737
0.0056,14.8459
0.0058,13.9935
0.006,13.1139
0.0062,12.3372
0.0064,11.6364
0.0066,10.9178

Specimen 16
The tested complete stress-strain curves
of concrete under uniaxial compression
Strain, Stress (MPa)
0,0
0.0002,7.36549
0.0004,14.0951
0.0006,20.4264
0.0008,26.2788
0.001,31.5549
0.0012,35.7497
0.0014,38.2016
0.0016,38.7639
0.0018,38.3693
0.002,37.5803
0.0022,36.544
0.0024,35.3421
0.0026,33.7036
0.0028,31.5929
0.003,29.3748
0.0032,27.6047
0.0034,26.0001
0.0036,24.5876
0.0038,23.3353
0.004,22.1497
0.0042,20.9539
0.0044,19.8966
0.0046,18.9987
0.0048,18.1119
0.005,17.2839
0.0052,16.4876
0.0054,15.8239
0.0056,15.2683
0.0058,14.6582
0.006,14.1317
0.0062,13.6272
0.0064,13.1535
0.0066,12.6326

Specimen 17
The tested complete stress-strain curves
of concrete under uniaxial compression
Strain, Stress (MPa)
0,0
0.0002,7.59442
0.0004,14.7401
0.0006,21.5092
0.0008,27.6467
0.001,32.8535
0.0012,36.4212
0.0014,38.6278
0.0016,39.7426
0.0018,40.4158
0.002,39.9613
0.0022,39.0868
0.0024,37.7705
0.0026,35.2592
0.0028,32.1144
0.003,28.9842
0.0032,26.2241
0.0034,23.9618
0.0036,22.1182
0.0038,20.6308
0.004,19.2486
0.0042,18.1171
0.0044,17.2674
0.0046,16.4749
0.0048,15.7307
0.005,15.0287
0.0052,14.3287
0.0054,13.629
0.0056,13.054
0.0058,12.5179
0.006,11.9957
0.0062,11.5136
0.0064,11.0365
0.0066,10.5726

Specimen 18
The tested complete stress-strain curves
of concrete under uniaxial compression
Strain, Stress (MPa)
0,0
0.0002,8.27038
0.0004,15.6083
0.0006,22.4912
0.0008,28.8554
0.001,34.4775
0.0012,39.182
0.0014,43.0832
0.0016,45.834
0.0018,47.2337
0.002,46.2471
0.0022,43.0134
0.0024,40.776
0.0026,39.0953
0.0028,36.8953
0.003,33.7651
0.0032,30.6421
0.0034,27.9754
0.0036,25.904
0.0038,24.1173
0.004,22.4825
0.0042,20.8
0.0044,19.2514
0.0046,18.1179
0.0048,16.8652
0.005,15.6361
0.0052,14.5559
0.0054,13.6607
0.0056,12.9125
0.0058,12.2451
0.006,11.707
0.0062,11.2029
0.0064,10.7665
0.0066,10.3973

Specimen 19
The tested complete stress-strain curves
of concrete under uniaxial compression
Strain, Stress (MPa)
0,0
0.0002,8.65792
0.0004,16.3526
0.0006,23.6247
0.0008,30.1451
0.001,35.6304
0.0012,39.7923
0.0014,41.5251
0.0016,41.9496
0.0018,41.887
0.002,40.269
0.0022,37.7202
0.0024,36.17
0.0026,35.328
0.0028,34.4464
0.003,32.8864
0.0032,31.0732
0.0034,29.1336
0.0036,27.3226
0.0038,25.6257
0.004,24.1304
0.0042,22.7588
0.0044,21.4149
0.0046,19.8352
0.0048,18.5287
0.005,17.4664
0.0052,16.4832
0.0054,15.5378
0.0056,14.7516
0.0058,13.9332
0.006,13.1844
0.0062,12.4575
0.0064,11.9831
0.0066,11.5225

Specimen 20
The tested complete stress-strain curves
of concrete under uniaxial compression
Strain, Stress (MPa)
0,0
0.0002,7.52672
0.0004,14.5313
0.0006,21.2902
0.0008,27.4517
0.001,32.9399
0.0012,37.3187
0.0014,39.6389
0.0016,41.8782
0.0018,42.4064
0.002,41.214
0.0022,38.8153
0.0024,37.1471
0.0026,34.8889
0.0028,32.594
0.003,30.2643
0.0032,28.0835
0.0034,26.1168
0.0036,24.4475
0.0038,23.0017
0.004,21.6331
0.0042,20.5389
0.0044,19.5632
0.0046,18.721
0.0048,17.8616
0.005,16.8754
0.0052,16.0733
0.0054,15.3061
0.0056,14.6301
0.0058,13.9503
0.006,13.355
0.0062,12.8046
0.0064,12.2884
0.0066,11.763

Specimen 21
The tested complete stress-strain curves
of concrete under uniaxial compression
Strain, Stress (MPa)
0,0
0.0002,8.1912
0.0004,15.5566
0.0006,22.0949
0.0008,27.6709
0.001,32.1761
0.0012,35.6291
0.0014,38.268
0.0016,40.0569
0.0018,41.0789
0.002,40.8991
0.0022,39.2535
0.0024,37.26
0.0026,35.7929
0.0028,34.4932
0.003,32.6263
0.0032,30.3842
0.0034,28.6185
0.0036,27.1167
0.0038,25.614
0.004,24.3224
0.0042,23.1371
0.0044,22.0083
0.0046,21.0408
0.0048,20.1644
0.005,19.3359
0.0052,18.4875
0.0054,17.6407
0.0056,16.8699
0.0058,16.1633
0.006,15.4482
0.0062,14.7578
0.0064,14.0908
0.0066,13.4517

Specimen 22
The tested complete stress-strain curves
of concrete under uniaxial compression
Strain, Stress (MPa)
0,0
0.0002,8.26626
0.0004,15.52112
0.0006,22.21962
0.0008,28.43024
0.001,33.80469
0.0012,37.95959
0.0014,40.67735
0.0016,41.41265
0.0018,41.12442
0.002,40.11118
0.0022,37.6853
0.0024,34.70221
0.0026,32.00086
0.0028,29.2356
0.003,26.31896
0.0032,23.48554
0.0034,20.96996
0.0036,18.99581
0.0038,17.43351
0.004,16.11124
0.0042,14.95427
0.0044,13.93923
0.0046,13.058
0.0048,12.30004
0.005,11.63622
0.0052,11.01377
0.0054,10.44313
0.0056,9.97155
0.0058,9.57422
0.006,9.24242
0.0062,8.93833
0.0064,8.57518
0.0066,8.21904

Specimen 23
The tested complete stress-strain curves
of concrete under uniaxial compression
Strain, Stress (MPa)
0,0
0.0002,8.12922
0.0004,15.07404
0.0006,21.16626
0.0008,26.51017
0.001,31.26118
0.0012,34.65895
0.0014,36.74299
0.0016,36.99484
0.0018,36.96613
0.002,36.44735
0.0022,35.41686
0.0024,34.08381
0.0026,32.03475
0.0028,29.80109
0.003,27.9313
0.0032,26.25712
0.0034,24.67593
0.0036,23.14805
0.0038,21.69936
0.004,20.42439
0.0042,19.31599
0.0044,18.27985
0.0046,17.31051
0.0048,16.33922
0.005,15.23691
0.0052,14.16162
0.0054,13.35213
0.0056,12.68118
0.0058,11.98714
0.006,11.30712
0.0062,10.69577
0.0064,10.14415
0.0066,9.67266

Specimen 24
The tested complete stress-strain curves
of concrete under uniaxial compression
Strain, Stress (MPa)
0,0
0.0002,8.71425
0.0004,16.19957
0.0006,22.47011
0.0008,27.39482
0.001,30.02392
0.0012,31.86309
0.0014,32.97423
0.0016,33.03324
0.0018,32.92015
0.002,32.78007
0.0022,32.4162
0.0024,31.42804
0.0026,30.25861
0.0028,28.99781
0.003,27.61113
0.0032,26.20924
0.0034,24.748
0.0036,23.41533
0.0038,22.28792
0.004,21.23056
0.0042,20.14696
0.0044,19.09138
0.0046,18.13925
0.0048,17.26295
0.005,16.34446
0.0052,15.38547
0.0054,14.55685
0.0056,13.86036
0.0058,13.21465
0.006,12.60935
0.0062,12.02772
0.0064,11.46545
0.0066,10.95353

Specimen 25
The tested complete stress-strain curves
of concrete under uniaxial compression
Strain, Stress (MPa)
0,0
0.0002,8.816
0.0004,16.05741
0.0006,22.37655
0.0008,27.972
0.001,32.61872
0.0012,35.54959
0.0014,36.80435
0.0016,36.66866
0.0018,36.24268
0.002,35.15129
0.0022,34.30765
0.0024,33.75282
0.0026,33.01481
0.0028,32.03822
0.003,30.73608
0.0032,28.78055
0.0034,26.55983
0.0036,24.61855
0.0038,23.16013
0.004,21.86106
0.0042,20.54038
0.0044,19.22306
0.0046,18.02874
0.0048,16.96912
0.005,16.02426
0.0052,15.18974
0.0054,14.45933
0.0056,13.83181
0.0058,13.296
0.006,12.85381
0.0062,12.45857
0.0064,12.08939
0.0066,11.77366

Specimen 26
The tested complete stress-strain curves
of concrete under uniaxial compression
Strain, Stress (MPa)
0,0
0.0002,7.77777
0.0004,14.38291
0.0006,20.57792
0.0008,26.3524
0.001,31.65568
0.0012,36.28241
0.0014,40.06942
0.0016,42.69517
0.0018,43.55291
0.002,42.58644
0.0022,41.22922
0.0024,39.33788
0.0026,37.13732
0.0028,34.47368
0.003,31.44454
0.0032,28.3053
0.0034,25.31133
0.0036,22.71054
0.0038,20.3333
0.004,18.07747
0.0042,16.0428
0.0044,14.32906
0.0046,12.93988
0.0048,11.76551
0.005,10.78967
0.0052,9.97942
0.0054,9.31201
0.0056,8.78235
0.0058,8.33564
0.006,7.89252
0.0062,7.50564
0.0064,7.23062
0.0066,6.99596

Specimen 27
The tested complete stress-strain curves
of concrete under uniaxial compression
Strain, Stress (MPa)
0,0
0.0002,8.04305
0.0004,15.00914
0.0006,21.70239
0.0008,27.94285
0.001,33.59694
0.0012,38.45043
0.0014,42.31546
0.0016,44.57831
0.0018,45.58048
0.002,45.05006
0.0022,43.45778
0.0024,41.37897
0.0026,38.7989
0.0028,36.16174
0.003,33.41429
0.0032,30.49006
0.0034,27.66378
0.0036,25.21017
0.0038,23.21812
0.004,21.47764
0.0042,19.94187
0.0044,18.57652
0.0046,17.37719
0.0048,16.3464
0.005,15.45359
0.0052,14.62283
0.0054,13.85013
0.0056,13.11579
0.0058,12.41752
0.006,11.76553
0.0062,11.15456
0.0064,10.56028
0.0066,9.98583

Specimen 28
The tested complete stress-strain curves
of concrete under uniaxial compression
Strain, Stress (MPa)
0,0
0.0002,8.29793
0.0004,15.32664
0.0006,21.93768
0.0008,28.08202
0.001,33.47447
0.0012,37.82607
0.0014,41.02197
0.0016,42.29364
0.0018,42.19362
0.002,41.78067
0.0022,39.99468
0.0024,37.07073
0.0026,33.56815
0.0028,30.0463
0.003,27.06452
0.0032,24.62115
0.0034,22.40127
0.0036,20.86074
0.0038,19.78868
0.004,18.82589
0.0042,17.88632
0.0044,17.08585
0.0046,16.44205
0.0048,15.86125
0.005,15.30991
0.0052,14.91183
0.0054,14.61226
0.0056,14.28995
0.0058,13.9055
0.006,13.29474
0.0062,12.81188
0.0064,12.52963
0.0066,12.25551

Specimen 29
The tested complete stress-strain curves
of concrete under uniaxial compression
Strain, Stress (MPa)
0,0
0.0002,7.90687
0.0004,14.92646
0.0006,21.74188
0.0008,28.11586
0.001,33.99617
0.0012,39.28671
0.0014,43.71007
0.0016,47.02536
0.0018,48.47919
0.002,48.72042
0.0022,47.94122
0.0024,45.54926
0.0026,42.17105
0.0028,38.44514
0.003,35.01005
0.0032,31.47131
0.0034,27.46675
0.0036,23.71565
0.0038,20.93733
0.004,19.54823
0.0042,18.67043
0.0044,17.76876
0.0046,16.85923
0.0048,16.04689
0.005,15.32483
0.0052,14.699
0.0054,14.1529
0.0056,13.62028
0.0058,13.09224
0.006,12.51162
0.0062,11.89199
0.0064,11.22303
0.0066,10.5564

Specimen 30
The tested complete stress-strain curves
of concrete under uniaxial compression
Strain, Stress (MPa)
0,0
0.0002,8.73484
0.0004,16.24535
0.0006,23.09017
0.0008,29.27162
0.001,34.29719
0.0012,37.44593
0.0014,38.2321
0.0016,37.93616
0.0018,37.37982
0.002,36.12708
0.0022,34.5718
0.0024,32.93849
0.0026,31.04991
0.0028,29.03997
0.003,27.0354
0.0032,24.87552
0.0034,22.71141
0.0036,20.86849
0.0038,19.42361
0.004,18.20245
0.0042,17.18102
0.0044,16.32335
0.0046,15.53825
0.0048,14.81543
0.005,14.14329
0.0052,13.51207
0.0054,12.98925
0.0056,12.55661
0.0058,12.1619
0.006,11.80995
0.0062,11.52009
0.0064,11.24848
0.0066,10.97498

Specimen 31
The tested complete stress-strain curves
of concrete under uniaxial compression
Strain, Stress (MPa)
0,0
0.0002,8.18681
0.0004,15.12708
0.0006,21.54531
0.0008,27.15863
0.001,31.85951
0.0012,35.93064
0.0014,39.10504
0.0016,41.12918
0.0018,42.22477
0.002,41.61436
0.0022,40.12468
0.0024,38.49965
0.0026,36.50799
0.0028,34.38544
0.003,32.01372
0.0032,29.52003
0.0034,27.18341
0.0036,25.13892
0.0038,23.22954
0.004,21.57802
0.0042,20.29214
0.0044,19.22776
0.0046,18.13359
0.0048,17.00302
0.005,16.02586
0.0052,15.21619
0.0054,14.55084
0.0056,14.03286
0.0058,13.54513
0.006,13.05703
0.0062,12.6045
0.0064,12.18599
0.0066,11.80595

Specimen 32
The tested complete stress-strain curves
of concrete under uniaxial compression
Strain, Stress (MPa)
0,0
0.0002,8.77498
0.0004,16.11658
0.0006,23.04441
0.0008,29.40922
0.001,34.94596
0.0012,39.71883
0.0014,43.56566
0.0016,46.41232
0.0018,47.76089
0.002,48.22175
0.0022,46.72473
0.0024,43.1923
0.0026,40.15938
0.0028,37.15834
0.003,34.2793
0.0032,31.85557
0.0034,29.99277
0.0036,28.35617
0.0038,26.65789
0.004,24.95784
0.0042,23.31134
0.0044,21.71701
0.0046,20.18366
0.0048,18.7762
0.005,17.45744
0.0052,16.29289
0.0054,15.33529
0.0056,14.52292
0.0058,13.82494
0.006,13.23635
0.0062,12.78506
0.0064,12.39526
0.0066,12.037

Specimen 33
The tested complete stress-strain curves
of concrete under uniaxial compression
Strain, Stress (MPa)
0,0
0.0002,10.05818
0.0004,17.85462
0.0006,24.93587
0.0008,31.16258
0.001,36.35748
0.0012,40.49718
0.0014,43.36829
0.0016,44.1889
0.0018,44.03936
0.002,42.20252
0.0022,40.44495
0.0024,38.84946
0.0026,36.9359
0.0028,34.31791
0.003,31.36046
0.0032,28.62449
0.0034,26.55461
0.0036,24.85466
0.0038,23.33339
0.004,21.92342
0.0042,20.63138
0.0044,19.37885
0.0046,18.14191
0.0048,17.08881
0.005,16.2735
0.0052,15.57076
0.0054,14.92156
0.0056,14.34807
0.0058,13.8573
0.006,13.40138
0.0062,12.95917
0.0064,12.58257
0.0066,12.2624